2025-05-26 14:23:54 - logging in using static token
2025-05-26 14:23:55 - Shard ID None has connected to Gateway (Session ID: c9934bd403fd6211c886038ed00ebed1).
2025-05-26 14:23:57 - Eingeloggt als 8Point#8406  
Synchronisiere neue Befehle...
2025-05-26 14:23:58 - Synchronisiert Server 1
2025-05-26 14:23:58 - Synchronisiert Server 2
2025-05-26 14:23:58 - Befehle wurden Synchronisiert! 
============================== 
Der Bot ist Bereit!
2025-05-26 14:24:11 - Befehl "8point-clans" ausgefuehrt mit action: show, clan_tag: None und position: 0
2025-05-26 14:24:12 - Ignoring exception in command '8point-clans'
Traceback (most recent call last):
  File "C:\Users\wroehner\AppData\Local\Programs\Python\Python313\Lib\site-packages\discord\app_commands\commands.py", line 858, in _do_call
    return await self._callback(interaction, **params)  # type: ignore
           ^^^^^^^^^^^^^^^^^^^^^^^^^^^^^^^^^^^^^^^^^^^
  File "C:\Users\wroehner\Desktop\Git\8Point\Python\main.py", line 259, in manage_8point_clans
    clans = load_clans()
  File "C:\Users\wroehner\Desktop\Git\8Point\Python\eight_point_json.py", line 10, in load_clans
    eight_point_clans = data.get([])
TypeError: unhashable type: 'list'

The above exception was the direct cause of the following exception:

Traceback (most recent call last):
  File "C:\Users\wroehner\AppData\Local\Programs\Python\Python313\Lib\site-packages\discord\app_commands\tree.py", line 1310, in _call
    await command._invoke_with_namespace(interaction, namespace)
  File "C:\Users\wroehner\AppData\Local\Programs\Python\Python313\Lib\site-packages\discord\app_commands\commands.py", line 883, in _invoke_with_namespace
    return await self._do_call(interaction, transformed_values)
           ^^^^^^^^^^^^^^^^^^^^^^^^^^^^^^^^^^^^^^^^^^^^^^^^^^^^
  File "C:\Users\wroehner\AppData\Local\Programs\Python\Python313\Lib\site-packages\discord\app_commands\commands.py", line 872, in _do_call
    raise CommandInvokeError(self, e) from e
discord.app_commands.errors.CommandInvokeError: Command '8point-clans' raised an exception: TypeError: unhashable type: 'list'
2025-05-26 14:34:56 - Shard ID None has successfully RESUMED session c9934bd403fd6211c886038ed00ebed1.
